Workbook

Sheet Traditional FIRE
B2: Traditional and Coast FI/RE Journey Summary
B4: Starting Inputs | F4: Projections
B5: Year | D5: 2026 | F5: Salary Growth Rate | H5: =(1+I5)/(1+I6)-1 -> 0 | I5: 0.03
B6: Age | D6: 33 | F6: Inflation Rate | H6: 0 | I6: 0.03
B7: Monthly Spend | D7: 6353 | F7: Effective Tax Rate | H7: 0.327
B8: PRETAX Annual Salary | D8: 294000 | F8: Investment Return | H8: =(1+I8)/(1+I6)-1 -> 0.038834951 | I8: 0.07
B9: Starting Investments | D9: 159291 | F9: Safe Withdrawal Rate | H9: 0.03
B10: Target Retirement Age | D10: 50 | F10: Estimated Monthly Spend in Retirement | H10: 8000
B12: Financial Independence Summary
B13: Traditional FI/RE | F13: Coast FIRE
B14: FI/RE NUMBER | D14: =(H10*12)/H9 -> 3200000 | F14: Coast FI/RE Number | H14: =D14/((1+(H8-H6))^(D10-D6)) -> 1674397.5
B15: Year: | D15: {=IFERROR(INDEX('Traditional FIRE'!$B$19:$B$67,MATCH(TRUE,'Traditional FIRE'!$R$19:$R$67="FI/RE",0)),"Not Reached")} -> 2061 | F15: Coast FI/RE Year | H15: {=IFERROR(INDEX('Traditional FIRE'!$B$20:$B$67, MATCH(TRUE, 'Traditional FIRE'!$N$20:$N$67>=H14, 0)), "Not Reached")} -> 2049
B16: Years to FI: | D16: =IFERROR(D15-'Traditional FIRE'!D5, "N/A") -> 35 | F16: Years to Coast FI/RE | H16: =IFERROR(H15-D5, "N/A") -> 23
A19: Age | B19: Calendar Year | C19: Year | D19: Annual Salary | E19: Monthly Income (after tax) | F19: Monthly Spend | G19: Monthly Spend Adjust | H19: Monthly Save | I19: Monthly Save Adjust | J19: Lump Sum/Annual Savings Adjustment | K19: Annual Spend | L19: Annual Saved | M19: Cumulative Savings | N19: Total Invested Balance (EOY) | O19: Investment Returns | P19: Safe Withdrawal | Q19: When Safe Withdrawal = Annual Spending | R19: Milestone
A20: =D6-1 -> 32 | B20: =D5-1 -> 2025 | C20: 0
A21: =D6 -> 33 | B21: ='Traditional FIRE'!D5 -> 2026 | C21: 1 | D21: ='Traditional FIRE'!D8 -> 294000 | E21: =D21*(1-'Traditional FIRE'!$H$7)/12 -> 16488.5 | F21: =D7 -> 6353 | H21: =E21-(F21+G21) -> 10135.5 | I21: -7326.46 | J21: 0 | K21: =(F21+G21)*12 -> 76236 | L21: =((H21+I21)*12)+J21 -> 33708.48 | M21: =L21+'Traditional FIRE'!D9 -> 192999.48 | N21: =(M21) -> 192999.48 | O21: =N21-M21 -> 0 | P21: =N21*'Traditional FIRE'!H9 -> 5789.9844 | Q21: =IFERROR(K21/P21, "N/A") -> 13.166875 | R21: =IF(N21>=$D$14, "FI/RE", IF(N21>=$H$14, "Coast FI/RE Achieved", "")) | T21: =H21+I21 -> 2809.04
A22: =A21+1 -> 34 | B22: =B21+1 -> 2027 | C22: =C21+1 -> 2 | D22: =D21*(1+'Traditional FIRE'!$H$5) -> 294000 | E22: =D22*(1-'Traditional FIRE'!$H$7)/12 -> 16488.5 | F22: =$D$7*(1+$H$6)^(C22-1) -> 6353 | H22: =E22-F22 -> 10135.5 | I22: -7326.46 | K22: =(F22+G22)*12 -> 76236 | L22: =((H22+I22)*12)+J22 -> 33708.48 | M22: =N21+L22 -> 226707.96 | N22: =(M22)*(1+'Traditional FIRE'!$H$8) -> 235512.15 | O22: =N22-M22 -> 8804.1926 | P22: =N22*'Traditional FIRE'!$H$9 -> 7065.3646 | Q22: =IFERROR(K22/P22, "N/A") -> 10.790101 | R22: =IF(N22>=$D$14, "FI/RE", IF(N22>=$H$14, "Coast FI/RE Achieved", ""))
A23: =A22+1 -> 35 | B23: =B22+1 -> 2028 | C23: =C22+1 -> 3 | D23: =D22*(1+'Traditional FIRE'!$H$5) -> 294000 | E23: =D23*(1-'Traditional FIRE'!$H$7)/12 -> 16488.5 | F23: =$D$7*(1+$H$6)^(C23-1) -> 6353 | H23: =E23-F23 -> 10135.5 | I23: -7326.46 | K23: =(F23+G23)*12 -> 76236 | L23: =((H23+I23)*12)+J23 -> 33708.48 | M23: =N22+L23 -> 269220.63 | N23: =(M23)*(1+'Traditional FIRE'!$H$8) -> 279675.8 | O23: =N23-M23 -> 10455.17 | P23: =N23*'Traditional FIRE'!$H$9 -> 8390.2741 | Q23: =IFERROR(K23/P23, "N/A") -> 9.0862348 | R23: =IF(N23>=$D$14, "FI/RE", IF(N23>=$H$14, "Coast FI/RE Achieved", ""))
A24: =A23+1 -> 36 | B24: =B23+1 -> 2029 | C24: =C23+1 -> 4 | D24: =D23*(1+'Traditional FIRE'!$H$5) -> 294000 | E24: =D24*(1-'Traditional FIRE'!$H$7)/12 -> 16488.5 | F24: =$D$7*(1+$H$6)^(C24-1) -> 6353 | H24: =E24-F24 -> 10135.5 | I24: -7326.46 | K24: =(F24+G24)*12 -> 76236 | L24: =((H24+I24)*12)+J24 -> 33708.48 | M24: =N23+L24 -> 313384.28 | N24: =(M24)*(1+'Traditional FIRE'!$H$8) -> 325554.55 | O24: =N24-M24 -> 12170.263 | P24: =N24*'Traditional FIRE'!$H$9 -> 9766.6364 | Q24: =IFERROR(K24/P24, "N/A") -> 7.805758 | R24: =IF(N24>=$D$14, "FI/RE", IF(N24>=$H$14, "Coast FI/RE Achieved", ""))
A25: =A24+1 -> 37 | B25: =B24+1 -> 2030 | C25: =C24+1 -> 5 | D25: =D24*(1+'Traditional FIRE'!$H$5) -> 294000 | E25: =D25*(1-'Traditional FIRE'!$H$7)/12 -> 16488.5 | F25: =$D$7*(1+$H$6)^(C25-1) -> 6353 | H25: =E25-F25 -> 10135.5 | I25: -7326.46 | K25: =(F25+G25)*12 -> 76236 | L25: =((H25+I25)*12)+J25 -> 33708.48 | M25: =N24+L25 -> 359263.03 | N25: =(M25)*(1+'Traditional FIRE'!$H$8) -> 373214.99 | O25: =N25-M25 -> 13951.962 | P25: =N25*'Traditional FIRE'!$H$9 -> 11196.45 | Q25: =IFERROR(K25/P25, "N/A") -> 6.8089441 | R25: =IF(N25>=$D$14, "FI/RE", IF(N25>=$H$14, "Coast FI/RE Achieved", ""))
A26: =A25+1 -> 38 | B26: =B25+1 -> 2031 | C26: =C25+1 -> 6 | D26: =D25*(1+'Traditional FIRE'!$H$5) -> 294000 | E26: =D26*(1-'Traditional FIRE'!$H$7)/12 -> 16488.5 | F26: =$D$7*(1+$H$6)^(C26-1) -> 6353 | H26: =E26-F26 -> 10135.5 | I26: -7326.46 | K26: =(F26+G26)*12 -> 76236 | L26: =((H26+I26)*12)+J26 -> 33708.48 | M26: =N25+L26 -> 406923.47 | N26: =(M26)*(1+'Traditional FIRE'!$H$8) -> 422726.32 | O26: =N26-M26 -> 15802.853 | P26: =N26*'Traditional FIRE'!$H$9 -> 12681.79 | Q26: =IFERROR(K26/P26, "N/A") -> 6.0114544 | R26: =IF(N26>=$D$14, "FI/RE", IF(N26>=$H$14, "Coast FI/RE Achieved", ""))
A27: =A26+1 -> 39 | B27: =B26+1 -> 2032 | C27: =C26+1 -> 7 | D27: =D26*(1+'Traditional FIRE'!$H$5) -> 294000 | E27: =D27*(1-'Traditional FIRE'!$H$7)/12 -> 16488.5 | F27: =$D$7*(1+$H$6)^(C27-1) -> 6353 | H27: =E27-F27 -> 10135.5 | I27: -7326.46 | K27: =(F27+G27)*12 -> 76236 | L27: =((H27+I27)*12)+J27 -> 33708.48 | M27: =N26+L27 -> 456434.8 | N27: =(M27)*(1+'Traditional FIRE'!$H$8) -> 474160.42 | O27: =N27-M27 -> 17725.623 | P27: =N27*'Traditional FIRE'!$H$9 -> 14224.813 | Q27: =IFERROR(K27/P27, "N/A") -> 5.3593676 | R27: =IF(N27>=$D$14, "FI/RE", IF(N27>=$H$14, "Coast FI/RE Achieved", ""))
A28: =A27+1 -> 40 | B28: =B27+1 -> 2033 | C28: =C27+1 -> 8 | D28: =D27*(1+'Traditional FIRE'!$H$5) -> 294000 | E28: =D28*(1-'Traditional FIRE'!$H$7)/12 -> 16488.5 | F28: =$D$7*(1+$H$6)^(C28-1) -> 6353 | H28: =E28-F28 -> 10135.5 | I28: -7326.46 | K28: =(F28+G28)*12 -> 76236 | L28: =((H28+I28)*12)+J28 -> 33708.48 | M28: =N27+L28 -> 507868.9 | N28: =(M28)*(1+'Traditional FIRE'!$H$8) -> 527591.97 | O28: =N28-M28 -> 19723.064 | P28: =N28*'Traditional FIRE'!$H$9 -> 15827.759 | Q28: =IFERROR(K28/P28, "N/A") -> 4.816601 | R28: =IF(N28>=$D$14, "FI/RE", IF(N28>=$H$14, "Coast FI/RE Achieved", ""))
A29: =A28+1 -> 41 | B29: =B28+1 -> 2034 | C29: =C28+1 -> 9 | D29: =D28*(1+'Traditional FIRE'!$H$5) -> 294000 | E29: =D29*(1-'Traditional FIRE'!$H$7)/12 -> 16488.5 | F29: =$D$7*(1+$H$6)^(C29-1) -> 6353 | H29: =E29-F29 -> 10135.5 | I29: -7326.46 | K29: =(F29+G29)*12 -> 76236 | L29: =((H29+I29)*12)+J29 -> 33708.48 | M29: =N28+L29 -> 561300.45 | N29: =(M29)*(1+'Traditional FIRE'!$H$8) -> 583098.52 | O29: =N29-M29 -> 21798.076 | P29: =N29*'Traditional FIRE'!$H$9 -> 17492.956 | Q29: =IFERROR(K29/P29, "N/A") -> 4.3580971 | R29: =IF(N29>=$D$14, "FI/RE", IF(N29>=$H$14, "Coast FI/RE Achieved", ""))
A30: =A29+1 -> 42 | B30: =B29+1 -> 2035 | C30: =C29+1 -> 10 | D30: =D29*(1+'Traditional FIRE'!$H$5) -> 294000 | E30: =D30*(1-'Traditional FIRE'!$H$7)/12 -> 16488.5 | F30: =$D$7*(1+$H$6)^(C30-1) -> 6353 | H30: =E30-F30 -> 10135.5 | I30: -7326.46 | K30: =(F30+G30)*12 -> 76236 | L30: =((H30+I30)*12)+J30 -> 33708.48 | M30: =N29+L30 -> 616807 | N30: =(M30)*(1+'Traditional FIRE'!$H$8) -> 640760.68 | O30: =N30-M30 -> 23953.67 | P30: =N30*'Traditional FIRE'!$H$9 -> 19222.82 | Q30: =IFERROR(K30/P30, "N/A") -> 3.9659113 | R30: =IF(N30>=$D$14, "FI/RE", IF(N30>=$H$14, "Coast FI/RE Achieved", ""))
A31: =A30+1 -> 43 | B31: =B30+1 -> 2036 | C31: =C30+1 -> 11 | D31: =D30*(1+'Traditional FIRE'!$H$5) -> 294000 | E31: =D31*(1-'Traditional FIRE'!$H$7)/12 -> 16488.5 | F31: =$D$7*(1+$H$6)^(C31-1) -> 6353 | H31: =E31-F31 -> 10135.5 | I31: -7326.46 | K31: =(F31+G31)*12 -> 76236 | L31: =((H31+I31)*12)+J31 -> 33708.48 | M31: =N30+L31 -> 674469.16 | N31: =(M31)*(1+'Traditional FIRE'!$H$8) -> 700662.13 | O31: =N31-M31 -> 26192.977 | P31: =N31*'Traditional FIRE'!$H$9 -> 21019.864 | Q31: =IFERROR(K31/P31, "N/A") -> 3.6268551 | R31: =IF(N31>=$D$14, "FI/RE", IF(N31>=$H$14, "Coast FI/RE Achieved", ""))
A32: =A31+1 -> 44 | B32: =B31+1 -> 2037 | C32: =C31+1 -> 12 | D32: =D31*(1+'Traditional FIRE'!$H$5) -> 294000 | E32: =D32*(1-'Traditional FIRE'!$H$7)/12 -> 16488.5 | F32: =$D$7*(1+$H$6)^(C32-1) -> 6353 | H32: =E32-F32 -> 10135.5 | I32: -7326.46 | K32: =(F32+G32)*12 -> 76236 | L32: =((H32+I32)*12)+J32 -> 33708.48 | M32: =N31+L32 -> 734370.61 | N32: =(M32)*(1+'Traditional FIRE'!$H$8) -> 762889.86 | O32: =N32-M32 -> 28519.247 | P32: =N32*'Traditional FIRE'!$H$9 -> 22886.696 | Q32: =IFERROR(K32/P32, "N/A") -> 3.3310182 | R32: =IF(N32>=$D$14, "FI/RE", IF(N32>=$H$14, "Coast FI/RE Achieved", ""))
A33: =A32+1 -> 45 | B33: =B32+1 -> 2038 | C33: =C32+1 -> 13 | D33: =D32*(1+'Traditional FIRE'!$H$5) -> 294000 | E33: =D33*(1-'Traditional FIRE'!$H$7)/12 -> 16488.5 | F33: =$D$7*(1+$H$6)^(C33-1) -> 6353 | H33: =E33-F33 -> 10135.5 | I33: -7326.46 | K33: =(F33+G33)*12 -> 76236 | L33: =((H33+I33)*12)+J33 -> 33708.48 | M33: =N32+L33 -> 796598.34 | N33: =(M33)*(1+'Traditional FIRE'!$H$8) -> 827534.2 | O33: =N33-M33 -> 30935.858 | P33: =N33*'Traditional FIRE'!$H$9 -> 24826.026 | Q33: =IFERROR(K33/P33, "N/A") -> 3.0708097 | R33: =IF(N33>=$D$14, "FI/RE", IF(N33>=$H$14, "Coast FI/RE Achieved", ""))
... A56: =A55+1 -> 68 | B56: =B55+1 -> 2061 | C56: =C55+1 -> 36 | D56: =D55*(1+'Traditional FIRE'!$H$5) -> 294000 | E56: =D56*(1-'Traditional FIRE'!$H$7)/12 -> 16488.5 | F56: =$D$7*(1+$H$6)^(C56-1) -> 6353 | H56: =E56-F56 -> 10135.5 | I56: -7326.46 | K56: =(F56+G56)*12 -> 76236 | L56: =((H56+I56)*12)+J56 -> 33708.48 | M56: =N55+L56 -> 3130334.9 | N56: =(M56)*(1+'Traditional FIRE'!$H$8) -> 3251901.3 | O56: =N56-M56 -> 121566.4 | P56: =N56*'Traditional FIRE'!$H$9 -> 97557.038 | Q56: =IFERROR(K56/P56, "N/A") -> 0.78145054 | R56: =IF(N56>=$D$14, "FI/RE", IF(N56>=$H$14, "Coast FI/RE Achieved", "")) -> FI/RE
A57: =A56+1 -> 69 | B57: =B56+1 -> 2062 | C57: =C55+1 -> 36 | D57: =D55*(1+'Traditional FIRE'!$H$5) -> 294000 | E57: =D57*(1-'Traditional FIRE'!$H$7)/12 -> 16488.5 | F57: =$D$7*(1+$H$6)^(C57-1) -> 6353 | H57: =E57-F57 -> 10135.5 | I57: -7326.46 | K57: =(F57+G57)*12 -> 76236 | L57: =((H57+I57)*12)+J57 -> 33708.48 | M57: =N56+L57 -> 3285609.8 | N57: =(M57)*(1+'Traditional FIRE'!$H$8) -> 3413206.2 | O57: =N57-M57 -> 127596.5 | P57: =N57*'Traditional FIRE'!$H$9 -> 102396.19 | Q57: =IFERROR(K57/P57, "N/A") -> 0.74451991 | R57: =IF(N57>=$D$14, "FI/RE", IF(N57>=$H$14, "Coast FI/RE Achieved", "")) -> FI/RE
A58: =A57+1 -> 70 | B58: =B57+1 -> 2063 | C58: =C57+1 -> 37 | D58: =D57*(1+'Traditional FIRE'!$H$5) -> 294000 | E58: =D58*(1-'Traditional FIRE'!$H$7)/12 -> 16488.5 | F58: =$D$7*(1+$H$6)^(C58-1) -> 6353 | H58: =E58-F58 -> 10135.5 | I58: -7326.46 | K58: =(F58+G58)*12 -> 76236 | L58: =((H58+I58)*12)+J58 -> 33708.48 | M58: =N57+L58 -> 3446914.7 | N58: =(M58)*(1+'Traditional FIRE'!$H$8) -> 3580775.5 | O58: =N58-M58 -> 133860.77 | P58: =N58*'Traditional FIRE'!$H$9 -> 107423.26 | Q58: =IFERROR(K58/P58, "N/A") -> 0.70967867 | R58: =IF(N58>=$D$14, "FI/RE", IF(N58>=$H$14, "Coast FI/RE Achieved", "")) -> FI/RE
A59: =A58+1 -> 71 | B59: =B58+1 -> 2064 | C59: =C58+1 -> 38 | D59: =D58*(1+'Traditional FIRE'!$H$5) -> 294000 | E59: =D59*(1-'Traditional FIRE'!$H$7)/12 -> 16488.5 | F59: =$D$7*(1+$H$6)^(C59-1) -> 6353 | H59: =E59-F59 -> 10135.5 | I59: -7326.46 | K59: =(F59+G59)*12 -> 76236 | L59: =((H59+I59)*12)+J59 -> 33708.48 | M59: =N58+L59 -> 3614484 | N59: =(M59)*(1+'Traditional FIRE'!$H$8) -> 3754852.3 | O59: =N59-M59 -> 140368.31 | P59: =N59*'Traditional FIRE'!$H$9 -> 112645.57 | Q59: =IFERROR(K59/P59, "N/A") -> 0.67677762 | R59: =IF(N59>=$D$14, "FI/RE", IF(N59>=$H$14, "Coast FI/RE Achieved", "")) -> FI/RE
A60: =A59+1 -> 72 | B60: =B59+1 -> 2065 | C60: =C59+1 -> 39 | D60: =D59*(1+'Traditional FIRE'!$H$5) -> 294000 | E60: =D60*(1-'Traditional FIRE'!$H$7)/12 -> 16488.5 | F60: =$D$7*(1+$H$6)^(C60-1) -> 6353 | H60: =E60-F60 -> 10135.5 | I60: -7326.46 | K60: =(F60+G60)*12 -> 76236 | L60: =((H60+I60)*12)+J60 -> 33708.48 | M60: =N59+L60 -> 3788560.8 | N60: =(M60)*(1+'Traditional FIRE'!$H$8) -> 3935689.3 | O60: =N60-M60 -> 147128.57 | P60: =N60*'Traditional FIRE'!$H$9 -> 118070.68 | Q60: =IFERROR(K60/P60, "N/A") -> 0.64568104 | R60: =IF(N60>=$D$14, "FI/RE", IF(N60>=$H$14, "Coast FI/RE Achieved", "")) -> FI/RE
A61: =A60+1 -> 73 | B61: =B60+1 -> 2066 | C61: =C60+1 -> 40 | D61: =D60*(1+'Traditional FIRE'!$H$5) -> 294000 | E61: =D61*(1-'Traditional FIRE'!$H$7)/12 -> 16488.5 | F61: =$D$7*(1+$H$6)^(C61-1) -> 6353 | H61: =E61-F61 -> 10135.5 | I61: -7326.46 | K61: =(F61+G61)*12 -> 76236 | L61: =((H61+I61)*12)+J61 -> 33708.48 | M61: =N60+L61 -> 3969397.8 | N61: =(M61)*(1+'Traditional FIRE'!$H$8) -> 4123549.2 | O61: =N61-M61 -> 154151.37 | P61: =N61*'Traditional FIRE'!$H$9 -> 123706.48 | Q61: =IFERROR(K61/P61, "N/A") -> 0.61626523 | R61: =IF(N61>=$D$14, "FI/RE", IF(N61>=$H$14, "Coast FI/RE Achieved", "")) -> FI/RE
A62: =A61+1 -> 74 | B62: =B61+1 -> 2067 | C62: =C61+1 -> 41 | D62: =D61*(1+'Traditional FIRE'!$H$5) -> 294000 | E62: =D62*(1-'Traditional FIRE'!$H$7)/12 -> 16488.5 | F62: =$D$7*(1+$H$6)^(C62-1) -> 6353 | H62: =E62-F62 -> 10135.5 | I62: -7326.46 | K62: =(F62+G62)*12 -> 76236 | L62: =((H62+I62)*12)+J62 -> 33708.48 | M62: =N61+L62 -> 4157257.7 | N62: =(M62)*(1+'Traditional FIRE'!$H$8) -> 4318704.6 | O62: =N62-M62 -> 161446.9 | P62: =N62*'Traditional FIRE'!$H$9 -> 129561.14 | Q62: =IFERROR(K62/P62, "N/A") -> 0.58841719 | R62: =IF(N62>=$D$14, "FI/RE", IF(N62>=$H$14, "Coast FI/RE Achieved", "")) -> FI/RE
A63: =A62+1 -> 75 | B63: =B62+1 -> 2068 | C63: =C62+1 -> 42 | D63: =D62*(1+'Traditional FIRE'!$H$5) -> 294000 | E63: =D63*(1-'Traditional FIRE'!$H$7)/12 -> 16488.5 | F63: =$D$7*(1+$H$6)^(C63-1) -> 6353 | H63: =E63-F63 -> 10135.5 | I63: -7326.46 | K63: =(F63+G63)*12 -> 76236 | L63: =((H63+I63)*12)+J63 -> 33708.48 | M63: =N62+L63 -> 4352413 | N63: =(M63)*(1+'Traditional FIRE'!$H$8) -> 4521438.8 | O63: =N63-M63 -> 169025.75 | P63: =N63*'Traditional FIRE'!$H$9 -> 135643.16 | Q63: =IFERROR(K63/P63, "N/A") -> 0.56203348 | R63: =IF(N63>=$D$14, "FI/RE", IF(N63>=$H$14, "Coast FI/RE Achieved", "")) -> FI/RE
A64: =A63+1 -> 76 | B64: =B63+1 -> 2069 | C64: =C63+1 -> 43 | D64: =D63*(1+'Traditional FIRE'!$H$5) -> 294000 | E64: =D64*(1-'Traditional FIRE'!$H$7)/12 -> 16488.5 | F64: =$D$7*(1+$H$6)^(C64-1) -> 6353 | H64: =E64-F64 -> 10135.5 | I64: -7326.46 | K64: =(F64+G64)*12 -> 76236 | L64: =((H64+I64)*12)+J64 -> 33708.48 | M64: =N63+L64 -> 4555147.3 | N64: =(M64)*(1+'Traditional FIRE'!$H$8) -> 4732046.2 | O64: =N64-M64 -> 176898.92 | P64: =N64*'Traditional FIRE'!$H$9 -> 141961.39 | Q64: =IFERROR(K64/P64, "N/A") -> 0.53701927 | R64: =IF(N64>=$D$14, "FI/RE", IF(N64>=$H$14, "Coast FI/RE Achieved", "")) -> FI/RE
A65: =A64+1 -> 77 | B65: =B64+1 -> 2070 | C65: =C64+1 -> 44 | D65: =D64*(1+'Traditional FIRE'!$H$5) -> 294000 | E65: =D65*(1-'Traditional FIRE'!$H$7)/12 -> 16488.5 | F65: =$D$7*(1+$H$6)^(C65-1) -> 6353 | H65: =E65-F65 -> 10135.5 | I65: -7326.46 | K65: =(F65+G65)*12 -> 76236 | L65: =((H65+I65)*12)+J65 -> 33708.48 | M65: =N64+L65 -> 4765754.7 | N65: =(M65)*(1+'Traditional FIRE'!$H$8) -> 4950832.5 | O65: =N65-M65 -> 185077.85 | P65: =N65*'Traditional FIRE'!$H$9 -> 148524.98 | Q65: =IFERROR(K65/P65, "N/A") -> 0.51328741 | R65: =IF(N65>=$D$14, "FI/RE", IF(N65>=$H$14, "Coast FI/RE Achieved", "")) -> FI/RE
A66: =A65+1 -> 78 | B66: =B65+1 -> 2071 | C66: =C65+1 -> 45 | D66: =D65*(1+'Traditional FIRE'!$H$5) -> 294000 | E66: =D66*(1-'Traditional FIRE'!$H$7)/12 -> 16488.5 | F66: =$D$7*(1+$H$6)^(C66-1) -> 6353 | H66: =E66-F66 -> 10135.5 | K66: =(F66+G66)*12 -> 76236 | L66: =((H66+I66)*12)+J66 -> 121626 | M66: =N65+L66 -> 5072458.5 | N66: =(M66)*(1+'Traditional FIRE'!$H$8) -> 5269447.2 | O66: =N66-M66 -> 196988.68 | P66: =N66*'Traditional FIRE'!$H$9 -> 158083.42 | Q66: =IFERROR(K66/P66, "N/A") -> 0.48225172 | R66: =IF(N66>=$D$14, "FI/RE", IF(N66>=$H$14, "Coast FI/RE Achieved", "")) -> FI/RE
A67: =A66+1 -> 79 | B67: =B66+1 -> 2072 | C67: =C66+1 -> 46 | D67: =D66*(1+'Traditional FIRE'!$H$5) -> 294000 | E67: =D67*(1-'Traditional FIRE'!$H$7)/12 -> 16488.5 | F67: =$D$7*(1+$H$6)^(C67-1) -> 6353 | H67: =E67-F67 -> 10135.5 | K67: =(F67+G67)*12 -> 76236 | L67: =((H67+I67)*12)+J67 -> 121626 | M67: =N66+L67 -> 5391073.2 | N67: =(M67)*(1+'Traditional FIRE'!$H$8) -> 5600435.3 | O67: =N67-M67 -> 209362.07 | P67: =N67*'Traditional FIRE'!$H$9 -> 168013.06 | Q67: =IFERROR(K67/P67, "N/A") -> 0.45375045 | R67: =IF(N67>=$D$14, "FI/RE", IF(N67>=$H$14, "Coast FI/RE Achieved", "")) -> FI/RE

Sheet Traditional FIRE Data Pulls
A21: Total Contributions | B21: % from Contributions | C21: Total Returns | D21: % from Returns
A23: ='Traditional FIRE'!D9+'Traditional FIRE'!L21 -> 192999.48 | B23: =IFERROR(A23/'Traditional FIRE'!N21, 0) -> 1 | C23: ='Traditional FIRE'!O21 -> 0 | D23: =IFERROR(C23/'Traditional FIRE'!N21, 0) -> 0
A24: =A23+'Traditional FIRE'!L22 -> 226707.96 | B24: =IFERROR(A24/'Traditional FIRE'!N22, 0) -> 0.96261682 | C24: =C23+'Traditional FIRE'!O22 -> 8804.1926 | D24: =IFERROR(C24/'Traditional FIRE'!N22, 0) -> 0.037383178
A25: =A24+'Traditional FIRE'!L23 -> 260416.44 | B25: =IFERROR(A25/'Traditional FIRE'!N23, 0) -> 0.93113683 | C25: =C24+'Traditional FIRE'!O23 -> 19259.363 | D25: =IFERROR(C25/'Traditional FIRE'!N23, 0) -> 0.068863172
A26: =A25+'Traditional FIRE'!L24 -> 294124.92 | B26: =IFERROR(A26/'Traditional FIRE'!N24, 0) -> 0.90345819 | C26: =C25+'Traditional FIRE'!O24 -> 31429.626 | D26: =IFERROR(C26/'Traditional FIRE'!N24, 0) -> 0.096541813
A27: =A26+'Traditional FIRE'!L25 -> 327833.4 | B27: =IFERROR(A27/'Traditional FIRE'!N25, 0) -> 0.87840363 | C27: =C26+'Traditional FIRE'!O25 -> 45381.588 | D27: =IFERROR(C27/'Traditional FIRE'!N25, 0) -> 0.12159637
A28: =A27+'Traditional FIRE'!L26 -> 361541.88 | B28: =IFERROR(A28/'Traditional FIRE'!N26, 0) -> 0.85526229 | C28: =C27+'Traditional FIRE'!O26 -> 61184.442 | D28: =IFERROR(C28/'Traditional FIRE'!N26, 0) -> 0.14473771
A29: =A28+'Traditional FIRE'!L27 -> 395250.36 | B29: =IFERROR(A29/'Traditional FIRE'!N27, 0) -> 0.83357939 | C29: =C28+'Traditional FIRE'!O27 -> 78910.065 | D29: =IFERROR(C29/'Traditional FIRE'!N27, 0) -> 0.16642061
A30: =A29+'Traditional FIRE'!L28 -> 428958.84 | B30: =IFERROR(A30/'Traditional FIRE'!N28, 0) -> 0.81305036 | C30: =C29+'Traditional FIRE'!O28 -> 98633.129 | D30: =IFERROR(C30/'Traditional FIRE'!N28, 0) -> 0.18694964
A31: =A30+'Traditional FIRE'!L29 -> 462667.32 | B31: =IFERROR(A31/'Traditional FIRE'!N29, 0) -> 0.79346337 | C31: =C30+'Traditional FIRE'!O29 -> 120431.2 | D31: =IFERROR(C31/'Traditional FIRE'!N29, 0) -> 0.20653663
A32: =A31+'Traditional FIRE'!L30 -> 496375.8 | B32: =IFERROR(A32/'Traditional FIRE'!N30, 0) -> 0.77466645 | C32: =C31+'Traditional FIRE'!O30 -> 144384.88 | D32: =IFERROR(C32/'Traditional FIRE'!N30, 0) -> 0.22533355
A33: =A32+'Traditional FIRE'!L31 -> 530084.28 | B33: =IFERROR(A33/'Traditional FIRE'!N31, 0) -> 0.75654764 | C33: =C32+'Traditional FIRE'!O31 -> 170577.85 | D33: =IFERROR(C33/'Traditional FIRE'!N31, 0) -> 0.24345236
A34: =A33+'Traditional FIRE'!L32 -> 563792.76 | B34: =IFERROR(A34/'Traditional FIRE'!N32, 0) -> 0.73902249 | C34: =C33+'Traditional FIRE'!O32 -> 199097.1 | D34: =IFERROR(C34/'Traditional FIRE'!N32, 0) -> 0.26097751
A35: =A34+'Traditional FIRE'!L33 -> 597501.24 | B35: =IFERROR(A35/'Traditional FIRE'!N33, 0) -> 0.72202604 | C35: =C34+'Traditional FIRE'!O33 -> 230032.96 | D35: =IFERROR(C35/'Traditional FIRE'!N33, 0) -> 0.27797396
... A69: =A68+'Traditional FIRE'!L67 -> 1919424.6 | B69: =IFERROR(A69/'Traditional FIRE'!N67, 0) -> 0.34272775 | C69: =C68+'Traditional FIRE'!O67 -> 3681010.7 | D69: =IFERROR(C69/'Traditional FIRE'!N67, 0) -> 0.65727225

Sheet Barista FIRE 
B2: Barista FI/RE Journey Summary
B4: Starting Inputs | F4: Projections
B5: Year | F5: Income Growth Rate
B6: Age | F6: Inflation Rate
B7: Monthly Spend | F7: Effective Tax Rate
B8: Annual Income | F8: Investment Return
B9: Current Portoflio Value | F9: Safe Withdrawal Rate
B10: Target Barista FI/RE Age | F10: % of Income Covered by Investments
B12: Barista FIRE Summary
B13: Targets | F13: Insights
B14: Target Nest Egg | D14: =IFERROR((D8*H10)/H9, "N/A") -> N/A | F14: Current Progress | H14: {=IFERROR((Index($M$20:$M$67,MATCH(TRUE,$B$20:$B$67=D5,0)))/D14, "N/A")} -> N/A
B15: Target Achieved | D15: {=IFERROR(Index($B$20:$B$67,MATCH(TRUE,$M$20:$M$67>=D14,0)), "N/A")} -> N/A | F15: =IFERROR(__xludf.DUMMYFUNCTION("IFERROR(sparkline(H14,{""charttype"",""bar"";""max"",100%;""color1"",""#a5c4dc"";""empty"",""zero""}), ""N/A"")"),"N/A") -> N/A
B16: Years to Target | D16: =IFERROR(D15-D5, "N/A") -> N/A
O18: BARISTA FIRE
A19: Age | B19: Calendar Year | C19: Year | D19: Annual Salary | E19: Monthly Income (after tax) | F19: Monthly Spend | G19: Monthly Spend Adjust | H19: Monthly Save | I19: Monthly Save Adjust | J19: Annual Save Adjust | K19: Annual Spend | L19: Annual Saved | M19: Total Invested Balance (EOY) | N19: Investment Returns | O19: Safe Withdrawal | P19: Part-Time Income Needed | Q19: Milestone
A20: =D6-1 -> -1 | B20: =D5-1 -> -1 | C20: 0
A21: =D6 | B21: ='Barista FIRE '!D5 | C21: 1 | D21: ='Barista FIRE '!D8 | E21: =D21*(1-'Barista FIRE '!$H$7)/12 -> 0 | F21: =D7 | H21: =E21-(F21+G21) -> 0 | K21: =(F21+G21)*12 -> 0 | L21: =((H21+I21)*12)+J21 -> 0 | M21: =D9+L21 -> 0 | N21: =M21-(D9+L21) -> 0 | O21: =M21*'Barista FIRE '!H9 -> 0 | P21: =IF(D21-O21 >=0, D21-O21, 0) -> 0 | Q21: =IF(O21>=(D21*$H$10), "Barista FIRE", "Working") -> Barista FIRE
A22: =A21+1 -> 1 | B22: =B21+1 -> 1 | C22: =C21+1 -> 2 | D22: =D21*(1+'Barista FIRE '!$H$5) -> 0 | E22: =D22*(1-'Barista FIRE '!$H$7)/12 -> 0 | F22: =$D$7*(1+$H$6)^(C22-1) -> 0 | H22: =E22-F22 -> 0 | K22: =(F22+G22)*12 -> 0 | L22: =((H22+I22)*12)+J22 -> 0 | M22: =(M21+L22)*(1+'Barista FIRE '!$H$8) -> 0 | N22: =M22-(L22+M21) -> 0 | O22: =M22*'Barista FIRE '!$H$9 -> 0 | P22: =IF(D22-O22 >=0, D22-O22, 0) -> 0 | Q22: =IF(O22>=(D22*$H$10), "Barista FIRE", "Working") -> Barista FIRE
A23: =A22+1 -> 2 | B23: =B22+1 -> 2 | C23: =C22+1 -> 3 | D23: =D22*(1+'Barista FIRE '!$H$5) -> 0 | E23: =D23*(1-'Barista FIRE '!$H$7)/12 -> 0 | F23: =$D$7*(1+$H$6)^(C23-1) -> 0 | H23: =E23-F23 -> 0 | K23: =(F23+G23)*12 -> 0 | L23: =((H23+I23)*12)+J23 -> 0 | M23: =(M22+L23)*(1+'Barista FIRE '!$H$8) -> 0 | N23: =M23-(L23+M22) -> 0 | O23: =M23*'Barista FIRE '!$H$9 -> 0 | P23: =IF(D23-O23 >=0, D23-O23, 0) -> 0 | Q23: =IF(O23>=(D23*$H$10), "Barista FIRE", "Working") -> Barista FIRE
A24: =A23+1 -> 3 | B24: =B23+1 -> 3 | C24: =C23+1 -> 4 | D24: =D23*(1+'Barista FIRE '!$H$5) -> 0 | E24: =D24*(1-'Barista FIRE '!$H$7)/12 -> 0 | F24: =$D$7*(1+$H$6)^(C24-1) -> 0 | H24: =E24-F24 -> 0 | K24: =(F24+G24)*12 -> 0 | L24: =((H24+I24)*12)+J24 -> 0 | M24: =(M23+L24)*(1+'Barista FIRE '!$H$8) -> 0 | N24: =M24-(L24+M23) -> 0 | O24: =M24*'Barista FIRE '!$H$9 -> 0 | P24: =IF(D24-O24 >=0, D24-O24, 0) -> 0 | Q24: =IF(O24>=(D24*$H$10), "Barista FIRE", "Working") -> Barista FIRE
A25: =A24+1 -> 4 | B25: =B24+1 -> 4 | C25: =C24+1 -> 5 | D25: =D24*(1+'Barista FIRE '!$H$5) -> 0 | E25: =D25*(1-'Barista FIRE '!$H$7)/12 -> 0 | F25: =$D$7*(1+$H$6)^(C25-1) -> 0 | H25: =E25-F25 -> 0 | K25: =(F25+G25)*12 -> 0 | L25: =((H25+I25)*12)+J25 -> 0 | M25: =(M24+L25)*(1+'Barista FIRE '!$H$8) -> 0 | N25: =M25-(L25+M24) -> 0 | O25: =M25*'Barista FIRE '!$H$9 -> 0 | P25: =IF(D25-O25 >=0, D25-O25, 0) -> 0 | Q25: =IF(O25>=(D25*$H$10), "Barista FIRE", "Working") -> Barista FIRE
A26: =A25+1 -> 5 | B26: =B25+1 -> 5 | C26: =C25+1 -> 6 | D26: =D25*(1+'Barista FIRE '!$H$5) -> 0 | E26: =D26*(1-'Barista FIRE '!$H$7)/12 -> 0 | F26: =$D$7*(1+$H$6)^(C26-1) -> 0 | H26: =E26-F26 -> 0 | K26: =(F26+G26)*12 -> 0 | L26: =((H26+I26)*12)+J26 -> 0 | M26: =(M25+L26)*(1+'Barista FIRE '!$H$8) -> 0 | N26: =M26-(L26+M25) -> 0 | O26: =M26*'Barista FIRE '!$H$9 -> 0 | P26: =IF(D26-O26 >=0, D26-O26, 0) -> 0 | Q26: =IF(O26>=(D26*$H$10), "Barista FIRE", "Working") -> Barista FIRE
A27: =A26+1 -> 6 | B27: =B26+1 -> 6 | C27: =C26+1 -> 7 | D27: =D26*(1+'Barista FIRE '!$H$5) -> 0 | E27: =D27*(1-'Barista FIRE '!$H$7)/12 -> 0 | F27: =$D$7*(1+$H$6)^(C27-1) -> 0 | H27: =E27-F27 -> 0 | K27: =(F27+G27)*12 -> 0 | L27: =((H27+I27)*12)+J27 -> 0 | M27: =(M26+L27)*(1+'Barista FIRE '!$H$8) -> 0 | N27: =M27-(L27+M26) -> 0 | O27: =M27*'Barista FIRE '!$H$9 -> 0 | P27: =IF(D27-O27 >=0, D27-O27, 0) -> 0 | Q27: =IF(O27>=(D27*$H$10), "Barista FIRE", "Working") -> Barista FIRE
A28: =A27+1 -> 7 | B28: =B27+1 -> 7 | C28: =C27+1 -> 8 | D28: =D27*(1+'Barista FIRE '!$H$5) -> 0 | E28: =D28*(1-'Barista FIRE '!$H$7)/12 -> 0 | F28: =$D$7*(1+$H$6)^(C28-1) -> 0 | H28: =E28-F28 -> 0 | K28: =(F28+G28)*12 -> 0 | L28: =((H28+I28)*12)+J28 -> 0 | M28: =(M27+L28)*(1+'Barista FIRE '!$H$8) -> 0 | N28: =M28-(L28+M27) -> 0 | O28: =M28*'Barista FIRE '!$H$9 -> 0 | P28: =IF(D28-O28 >=0, D28-O28, 0) -> 0 | Q28: =IF(O28>=(D28*$H$10), "Barista FIRE", "Working") -> Barista FIRE
A29: =A28+1 -> 8 | B29: =B28+1 -> 8 | C29: =C28+1 -> 9 | D29: =D28*(1+'Barista FIRE '!$H$5) -> 0 | E29: =D29*(1-'Barista FIRE '!$H$7)/12 -> 0 | F29: =$D$7*(1+$H$6)^(C29-1) -> 0 | H29: =E29-F29 -> 0 | K29: =(F29+G29)*12 -> 0 | L29: =((H29+I29)*12)+J29 -> 0 | M29: =(M28+L29)*(1+'Barista FIRE '!$H$8) -> 0 | N29: =M29-(L29+M28) -> 0 | O29: =M29*'Barista FIRE '!$H$9 -> 0 | P29: =IF(D29-O29 >=0, D29-O29, 0) -> 0 | Q29: =IF(O29>=(D29*$H$10), "Barista FIRE", "Working") -> Barista FIRE
A30: =A29+1 -> 9 | B30: =B29+1 -> 9 | C30: =C29+1 -> 10 | D30: =D29*(1+'Barista FIRE '!$H$5) -> 0 | E30: =D30*(1-'Barista FIRE '!$H$7)/12 -> 0 | F30: =$D$7*(1+$H$6)^(C30-1) -> 0 | H30: =E30-F30 -> 0 | K30: =(F30+G30)*12 -> 0 | L30: =((H30+I30)*12)+J30 -> 0 | M30: =(M29+L30)*(1+'Barista FIRE '!$H$8) -> 0 | N30: =M30-(L30+M29) -> 0 | O30: =M30*'Barista FIRE '!$H$9 -> 0 | P30: =IF(D30-O30 >=0, D30-O30, 0) -> 0 | Q30: =IF(O30>=(D30*$H$10), "Barista FIRE", "Working") -> Barista FIRE
A31: =A30+1 -> 10 | B31: =B30+1 -> 10 | C31: =C30+1 -> 11 | D31: =D30*(1+'Barista FIRE '!$H$5) -> 0 | E31: =D31*(1-'Barista FIRE '!$H$7)/12 -> 0 | F31: =$D$7*(1+$H$6)^(C31-1) -> 0 | H31: =E31-F31 -> 0 | K31: =(F31+G31)*12 -> 0 | L31: =((H31+I31)*12)+J31 -> 0 | M31: =(M30+L31)*(1+'Barista FIRE '!$H$8) -> 0 | N31: =M31-(L31+M30) -> 0 | O31: =M31*'Barista FIRE '!$H$9 -> 0 | P31: =IF(D31-O31 >=0, D31-O31, 0) -> 0 | Q31: =IF(O31>=(D31*$H$10), "Barista FIRE", "Working") -> Barista FIRE
A32: =A31+1 -> 11 | B32: =B31+1 -> 11 | C32: =C31+1 -> 12 | D32: =D31*(1+'Barista FIRE '!$H$5) -> 0 | E32: =D32*(1-'Barista FIRE '!$H$7)/12 -> 0 | F32: =$D$7*(1+$H$6)^(C32-1) -> 0 | H32: =E32-F32 -> 0 | K32: =(F32+G32)*12 -> 0 | L32: =((H32+I32)*12)+J32 -> 0 | M32: =(M31+L32)*(1+'Barista FIRE '!$H$8) -> 0 | N32: =M32-(L32+M31) -> 0 | O32: =M32*'Barista FIRE '!$H$9 -> 0 | P32: =IF(D32-O32 >=0, D32-O32, 0) -> 0 | Q32: =IF(O32>=(D32*$H$10), "Barista FIRE", "Working") -> Barista FIRE
A33: =A32+1 -> 12 | B33: =B32+1 -> 12 | C33: =C32+1 -> 13 | D33: =D32*(1+'Barista FIRE '!$H$5) -> 0 | E33: =D33*(1-'Barista FIRE '!$H$7)/12 -> 0 | F33: =$D$7*(1+$H$6)^(C33-1) -> 0 | H33: =E33-F33 -> 0 | K33: =(F33+G33)*12 -> 0 | L33: =((H33+I33)*12)+J33 -> 0 | M33: =(M32+L33)*(1+'Barista FIRE '!$H$8) -> 0 | N33: =M33-(L33+M32) -> 0 | O33: =M33*'Barista FIRE '!$H$9 -> 0 | P33: =IF(D33-O33 >=0, D33-O33, 0) -> 0 | Q33: =IF(O33>=(D33*$H$10), "Barista FIRE", "Working") -> Barista FIRE
... A56: =A55+1 -> 35 | B56: =B55+1 -> 35 | C56: =C55+1 -> 36 | D56: =D55*(1+'Barista FIRE '!$H$5) -> 0 | E56: =D56*(1-'Barista FIRE '!$H$7)/12 -> 0 | F56: =$D$7*(1+$H$6)^(C56-1) -> 0 | H56: =E56-F56 -> 0 | K56: =(F56+G56)*12 -> 0 | L56: =((H56+I56)*12)+J56 -> 0 | M56: =(M55+L56)*(1+'Barista FIRE '!$H$8) -> 0 | N56: =M56-(L56+M55) -> 0 | O56: =M56*'Barista FIRE '!$H$9 -> 0 | P56: =IF(D56-O56 >=0, D56-O56, 0) -> 0 | Q56: =IF(O56>=(D56*$H$10), "Barista FIRE", "Working") -> Barista FIRE
A57: =A56+1 -> 36 | B57: =B56+1 -> 36 | C57: =C55+1 -> 36 | D57: =D55*(1+'Barista FIRE '!$H$5) -> 0 | E57: =D57*(1-'Barista FIRE '!$H$7)/12 -> 0 | F57: =$D$7*(1+$H$6)^(C57-1) -> 0 | H57: =E57-F57 -> 0 | K57: =(F57+G57)*12 -> 0 | L57: =((H57+I57)*12)+J57 -> 0 | M57: =(M56+L57)*(1+'Barista FIRE '!$H$8) -> 0 | N57: =M57-(L57+M56) -> 0 | O57: =M57*'Barista FIRE '!$H$9 -> 0 | P57: =IF(D57-O57 >=0, D57-O57, 0) -> 0 | Q57: =IF(O57>=(D57*$H$10), "Barista FIRE", "Working") -> Barista FIRE
A58: =A57+1 -> 37 | B58: =B57+1 -> 37 | C58: =C57+1 -> 37 | D58: =D57*(1+'Barista FIRE '!$H$5) -> 0 | E58: =D58*(1-'Barista FIRE '!$H$7)/12 -> 0 | F58: =$D$7*(1+$H$6)^(C58-1) -> 0 | H58: =E58-F58 -> 0 | K58: =(F58+G58)*12 -> 0 | L58: =((H58+I58)*12)+J58 -> 0 | M58: =(M57+L58)*(1+'Barista FIRE '!$H$8) -> 0 | N58: =M58-(L58+M57) -> 0 | O58: =M58*'Barista FIRE '!$H$9 -> 0 | P58: =IF(D58-O58 >=0, D58-O58, 0) -> 0 | Q58: =IF(O58>=(D58*$H$10), "Barista FIRE", "Working") -> Barista FIRE
A59: =A58+1 -> 38 | B59: =B58+1 -> 38 | C59: =C58+1 -> 38 | D59: =D58*(1+'Barista FIRE '!$H$5) -> 0 | E59: =D59*(1-'Barista FIRE '!$H$7)/12 -> 0 | F59: =$D$7*(1+$H$6)^(C59-1) -> 0 | H59: =E59-F59 -> 0 | K59: =(F59+G59)*12 -> 0 | L59: =((H59+I59)*12)+J59 -> 0 | M59: =(M58+L59)*(1+'Barista FIRE '!$H$8) -> 0 | N59: =M59-(L59+M58) -> 0 | O59: =M59*'Barista FIRE '!$H$9 -> 0 | P59: =IF(D59-O59 >=0, D59-O59, 0) -> 0 | Q59: =IF(O59>=(D59*$H$10), "Barista FIRE", "Working") -> Barista FIRE
A60: =A59+1 -> 39 | B60: =B59+1 -> 39 | C60: =C59+1 -> 39 | D60: =D59*(1+'Barista FIRE '!$H$5) -> 0 | E60: =D60*(1-'Barista FIRE '!$H$7)/12 -> 0 | F60: =$D$7*(1+$H$6)^(C60-1) -> 0 | H60: =E60-F60 -> 0 | K60: =(F60+G60)*12 -> 0 | L60: =((H60+I60)*12)+J60 -> 0 | M60: =(M59+L60)*(1+'Barista FIRE '!$H$8) -> 0 | N60: =M60-(L60+M59) -> 0 | O60: =M60*'Barista FIRE '!$H$9 -> 0 | P60: =IF(D60-O60 >=0, D60-O60, 0) -> 0 | Q60: =IF(O60>=(D60*$H$10), "Barista FIRE", "Working") -> Barista FIRE
A61: =A60+1 -> 40 | B61: =B60+1 -> 40 | C61: =C60+1 -> 40 | D61: =D60*(1+'Barista FIRE '!$H$5) -> 0 | E61: =D61*(1-'Barista FIRE '!$H$7)/12 -> 0 | F61: =$D$7*(1+$H$6)^(C61-1) -> 0 | H61: =E61-F61 -> 0 | K61: =(F61+G61)*12 -> 0 | L61: =((H61+I61)*12)+J61 -> 0 | M61: =(M60+L61)*(1+'Barista FIRE '!$H$8) -> 0 | N61: =M61-(L61+M60) -> 0 | O61: =M61*'Barista FIRE '!$H$9 -> 0 | P61: =IF(D61-O61 >=0, D61-O61, 0) -> 0 | Q61: =IF(O61>=(D61*$H$10), "Barista FIRE", "Working") -> Barista FIRE
A62: =A61+1 -> 41 | B62: =B61+1 -> 41 | C62: =C61+1 -> 41 | D62: =D61*(1+'Barista FIRE '!$H$5) -> 0 | E62: =D62*(1-'Barista FIRE '!$H$7)/12 -> 0 | F62: =$D$7*(1+$H$6)^(C62-1) -> 0 | H62: =E62-F62 -> 0 | K62: =(F62+G62)*12 -> 0 | L62: =((H62+I62)*12)+J62 -> 0 | M62: =(M61+L62)*(1+'Barista FIRE '!$H$8) -> 0 | N62: =M62-(L62+M61) -> 0 | O62: =M62*'Barista FIRE '!$H$9 -> 0 | P62: =IF(D62-O62 >=0, D62-O62, 0) -> 0 | Q62: =IF(O62>=(D62*$H$10), "Barista FIRE", "Working") -> Barista FIRE
A63: =A62+1 -> 42 | B63: =B62+1 -> 42 | C63: =C62+1 -> 42 | D63: =D62*(1+'Barista FIRE '!$H$5) -> 0 | E63: =D63*(1-'Barista FIRE '!$H$7)/12 -> 0 | F63: =$D$7*(1+$H$6)^(C63-1) -> 0 | H63: =E63-F63 -> 0 | K63: =(F63+G63)*12 -> 0 | L63: =((H63+I63)*12)+J63 -> 0 | M63: =(M62+L63)*(1+'Barista FIRE '!$H$8) -> 0 | N63: =M63-(L63+M62) -> 0 | O63: =M63*'Barista FIRE '!$H$9 -> 0 | P63: =IF(D63-O63 >=0, D63-O63, 0) -> 0 | Q63: =IF(O63>=(D63*$H$10), "Barista FIRE", "Working") -> Barista FIRE
A64: =A63+1 -> 43 | B64: =B63+1 -> 43 | C64: =C63+1 -> 43 | D64: =D63*(1+'Barista FIRE '!$H$5) -> 0 | E64: =D64*(1-'Barista FIRE '!$H$7)/12 -> 0 | F64: =$D$7*(1+$H$6)^(C64-1) -> 0 | H64: =E64-F64 -> 0 | K64: =(F64+G64)*12 -> 0 | L64: =((H64+I64)*12)+J64 -> 0 | M64: =(M63+L64)*(1+'Barista FIRE '!$H$8) -> 0 | N64: =M64-(L64+M63) -> 0 | O64: =M64*'Barista FIRE '!$H$9 -> 0 | P64: =IF(D64-O64 >=0, D64-O64, 0) -> 0 | Q64: =IF(O64>=(D64*$H$10), "Barista FIRE", "Working") -> Barista FIRE
A65: =A64+1 -> 44 | B65: =B64+1 -> 44 | C65: =C64+1 -> 44 | D65: =D64*(1+'Barista FIRE '!$H$5) -> 0 | E65: =D65*(1-'Barista FIRE '!$H$7)/12 -> 0 | F65: =$D$7*(1+$H$6)^(C65-1) -> 0 | H65: =E65-F65 -> 0 | K65: =(F65+G65)*12 -> 0 | L65: =((H65+I65)*12)+J65 -> 0 | M65: =(M64+L65)*(1+'Barista FIRE '!$H$8) -> 0 | N65: =M65-(L65+M64) -> 0 | O65: =M65*'Barista FIRE '!$H$9 -> 0 | P65: =IF(D65-O65 >=0, D65-O65, 0) -> 0 | Q65: =IF(O65>=(D65*$H$10), "Barista FIRE", "Working") -> Barista FIRE
A66: =A65+1 -> 45 | B66: =B65+1 -> 45 | C66: =C65+1 -> 45 | D66: =D65*(1+'Barista FIRE '!$H$5) -> 0 | E66: =D66*(1-'Barista FIRE '!$H$7)/12 -> 0 | F66: =$D$7*(1+$H$6)^(C66-1) -> 0 | H66: =E66-F66 -> 0 | K66: =(F66+G66)*12 -> 0 | L66: =((H66+I66)*12)+J66 -> 0 | M66: =(M65+L66)*(1+'Barista FIRE '!$H$8) -> 0 | N66: =M66-(L66+M65) -> 0 | O66: =M66*'Barista FIRE '!$H$9 -> 0 | P66: =IF(D66-O66 >=0, D66-O66, 0) -> 0 | Q66: =IF(O66>=(D66*$H$10), "Barista FIRE", "Working") -> Barista FIRE
...
